Workbook

Sheet Orangeline
U1: 45919 | W1: TFl
U2: =HLOOKUP(W2,Daten!$AC$1:$AE$24,Daten!AB24,0) -> Sprache | W2: GER
U4: =HLOOKUP(W2,Daten!$AC$1:$AE$30,Daten!AB29,0) -> Wandprofil
U5: Standard
U6: =HLOOKUP(W2,Daten!$AC$1:$AE$30,Daten!AB30,0) -> Standard | V6: =HLOOKUP(W2,Daten!$AC$1:$AE$31,Daten!AB31,0) -> XL
B10: =IFERROR(IF(B18="-","= 0 mm","= " & TEXT(B18,"#")&" mm"),"") -> = 2400 mm | C10: =IFERROR(IF(C18="-","= 0 mm","= " & TEXT(C18,"#")&" mm"),"") -> = 5000 mm | D10: =IFERROR(IF(D18="-","= 0 mm","= " & TEXT(D18,"#")&" mm"),"") -> = 3102 mm | E10: =IFERROR(IF(E18="-","0 mm =",TEXT(E18,"#")&" mm ="),"") -> 0 mm = | F10: =IFERROR(IF(F18="-","= 0°","= " & TEXT(F18,"0,0")&"°"),"") -> = 8,0° | G10: =IFERROR(IF(G18="-","= 0 mm/m","= " & TEXT(G18,"0,0")&" mm/m"),"") -> = 140,5 mm/m | H10: =IFERROR(IF(H18="-","= 0°","= " & TEXT(H18,"0,0")&"°"),"") -> = 0° | I10: =IFERROR(IF(I18="-","= 0 mm","= " & TEXT(I18,"#")&" mm"),"") -> = 4943 mm | J10: =IFERROR(IF(J18="-","= 0 mm","= " & TEXT(J18,"#")&" mm"),"") -> = 4900 mm | K10: =IFERROR(IF(K18="-","= 0 mm","= " & TEXT(K18,"#")&" mm"),"") -> = 0 mm | L10: =IFERROR(IF(L18="-","= 0 mm","= " & TEXT(L18,"#")&" mm"),"") -> = 5013 mm | M10: =IFERROR(IF(M18="-","= 0 mm","= " & TEXT(M18,"#")&" mm"),"") -> = 0 mm | N10: =IFERROR(IF(N18="-","= 0 mm","= " & TEXT(N18,"#")&" mm"),"") -> = 0 mm | O10: =IFERROR(IF(O18="-","= 0 mm","= " & TEXT(O18,"#")&" mm"),"") -> = 4888 mm | P10: =IFERROR(IF(OR(P18="-",P18="Option select!"),"= 0 mm","= " & TEXT(P18,"#")&" mm"),"") -> = 3259 mm | Q10: =IFERROR(IF(Q18="-","= 0 mm","= " & TEXT(Q18,"#")&" mm"),"") -> = 4998 mm | R10: =IFERROR(IF(R18="-","= 0 mm","= " & TEXT(R18,"#")&" mm"),"") -> = 5115 mm | S10: =IFERROR(IF(S18="-","= 0 mm","= " & TEXT(S18,"#")&" mm"),"") -> = 2416 mm | T10: =IFERROR(IF(T18="-","= 0 mm","= " & TEXT(T18,"#")&" mm"),"") -> = 4888 mm | U10: =IFERROR(IF(U18="-","= 0 mm","= " & TEXT(U18,"#")&" mm"),"") -> = 39 mm | V10: =IFERROR(IF(V18="-","= 0 mm","= " & TEXT(V18,"#")&" mm"),"") -> = 726 mm | W10: =IFERROR(IF(W18="-","= 0 mm","= " & TEXT(W18,"#")&" mm"),"") -> = 3102 mm
A11: =HLOOKUP(W2,Daten!$AC$1:$AE$22,Daten!AB3,0) -> Berechnung der Höhe und Tiefe einer Veranda | S11: =HLOOKUP(W2,Daten!$AC$1:$AE$23,Daten!AB23,0) -> Berechnung der Fensterelemente
B12: =HLOOKUP(W2,Daten!$AC$1:$AE$26,Daten!AB4,0) -> Höhe - Unterkante Rinne [mm] (H3) | C12: =HLOOKUP(W2,Daten!$AC$1:$AE$22,Daten!AB5,0) -> Bestelltiefe [mm] | D12: =HLOOKUP(W2,Daten!$AC$1:$AE$26,Daten!AB6,0) -> Höhe - Unterkante Wandprofil [mm] (H1) | E12: =HLOOKUP(W2,Daten!$AC$1:$AE$26,Daten!AB25,0) -> Dachüberstand [mm] (U1) | F12: =HLOOKUP(W2,Daten!$AC$1:$AE$26,Daten!AB7,0) -> Neigung [°] (α) | G12: =HLOOKUP(W2,Daten!$AC$1:$AE$27,Daten!AB27,0) -> Neigung [mm/m] | H12: =HLOOKUP(W2,Daten!$AC$1:$AE$26,Daten!AB26,0) -> Neigung Glas Ultraline [°] (β) | I12: =HLOOKUP(W2,Daten!$AC$1:$AE$22,Daten!AB8,0) -> Tiefe - Hinterkante Wandanschluss bis Mitte Pfosten [mm] (D1) | J12: =HLOOKUP(W2,Daten!$AC$1:$AE$22,Daten!AB9,0) -> Länge - Sparren Mitte [mm] (S1) | K12: =HLOOKUP(W2,Daten!$AC$1:$AE$22,Daten!AB10,0) -> Länge - Sparren Außen [mm] (S1) | L12: =HLOOKUP(W2,Daten!$AC$1:$AE$22,Daten!AB11,0) -> Tiefe - Hinterkante Wandanschluss bis Rinne Standard [mm] (D3) | M12: =HLOOKUP(W2,Daten!$AC$1:$AE$22,Daten!AB12,0) -> Tiefe - Hinterkante Wandanschluss bis Zierleiste rund [mm] (D3) | N12: =HLOOKUP(W2,Daten!$AC$1:$AE$22,Daten!AB13,0) -> Tiefe - Hinterkante Wandanschluss bis Zierleiste klassik [mm] (D3) | O12: =HLOOKUP(W2,Daten!$AC$1:$AE$22,Daten!AB14,0) -> Tiefe - Hinterkante Wandanschluss bis Innenkante Pfosten [mm] (D2) | P12: =HLOOKUP(W2,Daten!$AC$1:$AE$22,Daten!AB15,0) -> Höhe - Oberkante Wandprofil [mm] (H2) | Q12: =HLOOKUP(W2,Daten!$AC$1:$AE$22,Daten!AB21,0) -> Hinterkante Wandanschluss bis Außenkante Pfosten [mm] (D4) | R12: =HLOOKUP(W2,Daten!$AC$1:$AE$22,Daten!AB22,0) -> Hinterkante Wandanschluss bis Außenkante Pfosten [mm] (D5) | S12: =HLOOKUP(W2,Daten!$AC$1:$AE$22,Daten!AB16,0) -> Fensterhöhe Rinnenseite [mm] | T12: =HLOOKUP(W2,Daten!$AC$1:$AE$22,Daten!AB17,0) -> Fensterbreite [mm] | U12: =HLOOKUP(W2,Daten!$AC$1:$AE$22,Daten!AB18,0) -> Keilhöhe Rinnenseite [mm] | V12: =HLOOKUP(W2,Daten!$AC$1:$AE$22,Daten!AB19,0) -> Keilhöhe Hausseite [mm] | W12: =HLOOKUP(W2,Daten!$AC$1:$AE$22,Daten!AB20,0) -> Fensterhöhe Hausseite [mm]
A17: Type
A18: Orangeline | B18: 2400 | C18: 5000 | D18: =Daten!D18 -> 3101.9482 | E18: =Daten!E18 -> - | F18: =Daten!F18 -> 8 | G18: =Daten!G18 -> 140.54083 | H18: =Daten!H18 -> - | I18: =Daten!I18 -> 4943.3135 | J18: =Daten!J18 -> 4900 | K18: =Daten!K18 -> - | ... O18: =Daten!O18 -> 4888.3135 | P18: =IF(U5=U6,Daten!P18,IF(U5=V6,Daten!X18,"Option Select!")) -> 3258.9482 | Q18: =Daten!Q18 -> 4998.3135 | R18: =Daten!R18 -> 5115.3135 | S18: =Daten!S18 -> 2415.7 | T18: =Daten!T18 -> 4888.3135 | U18: =Daten!U18 -> 39 | V18: =Daten!V18 -> 725.74819 | W18: =Daten!W18 -> 3101.9482
A21: Gelbe Zellen manuell ausfüllen!

Sheet Orangeline+
U1: =Orangeline!U1 -> 45919 | W1: TFl
U2: =HLOOKUP(W2,Daten!$AC$1:$AE$24,Daten!AB24,0) -> Sprache | W2: GER
U4: =HLOOKUP(W2,Daten!$AC$1:$AE$30,Daten!AB29,0) -> Wandprofil
U5: Standard
U6: =HLOOKUP(W2,Daten!$AC$1:$AE$30,Daten!AB30,0) -> Standard | V6: =HLOOKUP(W2,Daten!$AC$1:$AE$31,Daten!AB31,0) -> XL
B10: =IFERROR(IF(B18="-","= 0 mm","= " & TEXT(B18,"#")&" mm"),"") -> = 2250 mm | C10: =IFERROR(IF(C18="-","= 0 mm","= " & TEXT(C18,"#")&" mm"),"") -> = 5000 mm | D10: =IFERROR(IF(D18="-","= 0 mm","= " & TEXT(D18,"#")&" mm"),"") -> = 2972 mm | E10: =IFERROR(IF(E18="-","0 mm =",TEXT(E18,"#")&" mm ="),"") -> 0 mm = | F10: =IFERROR(IF(F18="-","= 0°","= " & TEXT(F18,"0,0")&"°"),"") -> = 8,0° | G10: =IFERROR(IF(G18="-","= 0 mm/m","= " & TEXT(G18,"0,0")&" mm/m"),"") -> = 140,5 mm/m | H10: =IFERROR(IF(H18="-","= 0°","= " & TEXT(H18,"0,0")&"°"),"") -> = 0° | I10: =IFERROR(IF(I18="-","= 0 mm","= " & TEXT(I18,"#")&" mm"),"") -> = 4956 mm | J10: =IFERROR(IF(J18="-","= 0 mm","= " & TEXT(J18,"#")&" mm"),"") -> = 4900 mm | K10: =IFERROR(IF(K18="-","= 0 mm","= " & TEXT(K18,"#")&" mm"),"") -> = 0 mm | L10: =IFERROR(IF(L18="-","= 0 mm","= " & TEXT(L18,"#")&" mm"),"") -> = 5046 mm | M10: =IFERROR(IF(M18="-","= 0 mm","= " & TEXT(M18,"#")&" mm"),"") -> = 0 mm | N10: =IFERROR(IF(N18="-","= 0 mm","= " & TEXT(N18,"#")&" mm"),"") -> = 0 mm | O10: =IFERROR(IF(O18="-","= 0 mm","= " & TEXT(O18,"#")&" mm"),"") -> = 4901 mm | P10: =IFERROR(IF(OR(P18="-",P18="Option select!"),"= 0 mm","= " & TEXT(P18,"#")&" mm"),"") -> = 3129 mm | Q10: =IFERROR(IF(Q18="-","= 0 mm","= " & TEXT(Q18,"#")&" mm"),"") -> = 5011 mm | R10: =IFERROR(IF(R18="-","= 0 mm","= " & TEXT(R18,"#")&" mm"),"") -> = 5128 mm | S10: =IFERROR(IF(S18="-","= 0 mm","= " & TEXT(S18,"#")&" mm"),"") -> = 2284 mm | T10: =IFERROR(IF(T18="-","= 0 mm","= " & TEXT(T18,"#")&" mm"),"") -> = 4901 mm | U10: =IFERROR(IF(U18="-","= 0 mm","= " & TEXT(U18,"#")&" mm"),"") -> = 34 mm | V10: =IFERROR(IF(V18="-","= 0 mm","= " & TEXT(V18,"#")&" mm"),"") -> = 722 mm | W10: =IFERROR(IF(W18="-","= 0 mm","= " & TEXT(W18,"#")&" mm"),"") -> = 2972 mm
A11: =HLOOKUP(W2,Daten!$AC$1:$AE$22,Daten!AB3,0) -> Berechnung der Höhe und Tiefe einer Veranda | S11: =HLOOKUP(W2,Daten!$AC$1:$AE$23,Daten!AB23,0) -> Berechnung der Fensterelemente
B12: =HLOOKUP(W2,Daten!$AC$1:$AE$26,Daten!AB4,0) -> Höhe - Unterkante Rinne [mm] (H3) | C12: =HLOOKUP(W2,Daten!$AC$1:$AE$22,Daten!AB5,0) -> Bestelltiefe [mm] | D12: =HLOOKUP(W2,Daten!$AC$1:$AE$26,Daten!AB6,0) -> Höhe - Unterkante Wandprofil [mm] (H1) | E12: =HLOOKUP(W2,Daten!$AC$1:$AE$26,Daten!AB25,0) -> Dachüberstand [mm] (U1) | F12: =HLOOKUP(W2,Daten!$AC$1:$AE$26,Daten!AB7,0) -> Neigung [°] (α) | G12: =HLOOKUP(W2,Daten!$AC$1:$AE$27,Daten!AB27,0) -> Neigung [mm/m] | H12: =HLOOKUP(W2,Daten!$AC$1:$AE$26,Daten!AB26,0) -> Neigung Glas Ultraline [°] (β) | I12: =HLOOKUP(W2,Daten!$AC$1:$AE$22,Daten!AB8,0) -> Tiefe - Hinterkante Wandanschluss bis Mitte Pfosten [mm] (D1) | J12: =HLOOKUP(W2,Daten!$AC$1:$AE$22,Daten!AB9,0) -> Länge - Sparren Mitte [mm] (S1) | K12: =HLOOKUP(W2,Daten!$AC$1:$AE$22,Daten!AB10,0) -> Länge - Sparren Außen [mm] (S1) | L12: =HLOOKUP(W2,Daten!$AC$1:$AE$22,Daten!AB11,0) -> Tiefe - Hinterkante Wandanschluss bis Rinne Standard [mm] (D3) | M12: =HLOOKUP(W2,Daten!$AC$1:$AE$22,Daten!AB12,0) -> Tiefe - Hinterkante Wandanschluss bis Zierleiste rund [mm] (D3) | N12: =HLOOKUP(W2,Daten!$AC$1:$AE$22,Daten!AB13,0) -> Tiefe - Hinterkante Wandanschluss bis Zierleiste klassik [mm] (D3) | O12: =HLOOKUP(W2,Daten!$AC$1:$AE$22,Daten!AB14,0) -> Tiefe - Hinterkante Wandanschluss bis Innenkante Pfosten [mm] (D2) | P12: =HLOOKUP(W2,Daten!$AC$1:$AE$22,Daten!AB15,0) -> Höhe - Oberkante Wandprofil [mm] (H2) | Q12: =HLOOKUP(W2,Daten!$AC$1:$AE$22,Daten!AB21,0) -> Hinterkante Wandanschluss bis Außenkante Pfosten [mm] (D4) | R12: =HLOOKUP(W2,Daten!$AC$1:$AE$22,Daten!AB22,0) -> Hinterkante Wandanschluss bis Außenkante Pfosten [mm] (D5) | S12: =HLOOKUP(W2,Daten!$AC$1:$AE$22,Daten!AB16,0) -> Fensterhöhe Rinnenseite [mm] | T12: =HLOOKUP(W2,Daten!$AC$1:$AE$22,Daten!AB17,0) -> Fensterbreite [mm] | U12: =HLOOKUP(W2,Daten!$AC$1:$AE$22,Daten!AB18,0) -> Keilhöhe Rinnenseite [mm] | V12: =HLOOKUP(W2,Daten!$AC$1:$AE$22,Daten!AB19,0) -> Keilhöhe Hausseite [mm] | W12: =HLOOKUP(W2,Daten!$AC$1:$AE$22,Daten!AB20,0) -> Fensterhöhe Hausseite [mm]
A17: Type
A18: Orangeline+ | B18: 2250 | C18: 5000 | D18: =Daten!D19 -> 2971.8828 | E18: =Daten!E19 -> - | F18: =Daten!F19 -> 8 | G18: =Daten!G19 -> 140.54083 | H18: =Daten!H19 -> - | I18: =Daten!I19 -> 4956.2917 | J18: =Daten!J19 -> 4900 | K18: =Daten!K19 -> - | ... O18: =Daten!O19 -> 4901.2917 | P18: =IF(U5=U6,Daten!P19,IF(U5=V6,Daten!X19,"Option Select!")) -> 3129.0628 | Q18: =Daten!Q19 -> 5011.2917 | R18: =Daten!R19 -> 5128.2917 | S18: =Daten!S19 -> 2284 | T18: =Daten!T19 -> 4901.2917 | U18: =Daten!U19 -> 34 | V18: =Daten!V19 -> 721.88279 | W18: =Daten!W19 -> 2971.8828
A21: Gelbe Zellen manuell ausfüllen!

Sheet Trendline
U1: =Orangeline!U1 -> 45919 | W1: TFl
U2: =HLOOKUP(W2,Daten!$AC$1:$AE$24,Daten!AB24,0) -> Sprache | W2: GER
W3: {=IFERROR(_xlfn.IFS(U8=U9,L10,U8=V9,M10,U8=W9,N10),"= 0")} -> = 4173 mm
U4: =HLOOKUP(W2,Daten!$AC$1:$AE$30,Daten!AB29,0) -> Wandprofil
U5: Standard
U6: =HLOOKUP(W2,Daten!$AC$1:$AE$30,Daten!AB30,0) -> Standard | V6: =HLOOKUP(W2,Daten!$AC$1:$AE$31,Daten!AB31,0) -> XL
U7: =HLOOKUP($W$2,Daten!$AC$1:$AE$35,Daten!AB32,0) -> Zierleiste
U8: Standard
U9: =HLOOKUP(W2,Daten!$AC$1:$AE$30,Daten!AB30,0) -> Standard | V9: =HLOOKUP(W2,Daten!$AC$1:$AE$35,Daten!AB33,0) -> Rund | W9: =HLOOKUP(W2,Daten!$AC$1:$AE$35,Daten!AB34,0) -> Klassik
B10: =IFERROR(IF(B18="-","= 0 mm","= " & TEXT(B18,"#")&" mm"),"") -> = 2250 mm | C10: =IFERROR(IF(C18="-","= 0 mm","= " & TEXT(C18,"#")&" mm"),"") -> = 4050 mm | D10: =IFERROR(IF(D18="-","= 0 mm","= " & TEXT(D18,"#")&" mm"),"") -> = 2700 mm | E10: =IFERROR(IF(E18="-","0 mm =",TEXT(E18,"#")&" mm ="),"") -> 0 mm = | F10: =IFERROR(IF(F18="-","= 0°","= " & TEXT(F18,"0,0")&"°"),"") -> = 5,8° | G10: =IFERROR(IF(G18="-","= 0 mm/m","= " & TEXT(G18,"0,0")&" mm/m"),"") -> = 102,3 mm/m | H10: =IFERROR(IF(H18="-","= 0°","= " & TEXT(H18,"0,0")&"°"),"") -> = 0° | I10: =IFERROR(IF(I18="-","= 0 mm","= " & TEXT(I18,"#")&" mm"),"") -> = 4061 mm | J10: =IFERROR(IF(J18="-","= 0 mm","= " & TEXT(J18,"#")&" mm"),"") -> = 3950 mm | K10: =IFERROR(IF(K18="-","= 0 mm","= " & TEXT(K18,"#")&" mm"),"") -> = 0 mm | L10: =IFERROR(IF(L18="-","= 0 mm","= " & TEXT(L18,"#")&" mm"),"") -> = 4173 mm | M10: =IFERROR(IF(M18="-","= 0 mm","= " & TEXT(M18,"#")&" mm"),"") -> = 4177 mm | N10: =IFERROR(IF(N18="-","= 0 mm","= " & TEXT(N18,"#")&" mm"),"") -> = 4219 mm | O10: =IFERROR(IF(O18="-","= 0 mm","= " & TEXT(O18,"#")&" mm"),"") -> = 4006 mm | P10: =IFERROR(IF(OR(P18="-",P18="Option select!"),"= 0 mm","= " & TEXT(P18,"#")&" mm"),"") -> = 2862 mm | Q10: =IFERROR(IF(Q18="-","= 0 mm","= " & TEXT(Q18,"#")&" mm"),"") -> = 4116 mm | R10: =IFERROR(IF(R18="-","= 0 mm","= " & TEXT(R18,"#")&" mm"),"") -> = 4233 mm | S10: =IFERROR(IF(S18="-","= 0 mm","= " & TEXT(S18,"#")&" mm"),"") -> = 2289 mm | T10: =IFERROR(IF(T18="-","= 0 mm","= " & TEXT(T18,"#")&" mm"),"") -> = 4006 mm
A11: =HLOOKUP(W2,Daten!$AC$1:$AE$22,Daten!AB3,0) -> Berechnung der Höhe und Tiefe einer Veranda | S11: =HLOOKUP(W2,Daten!$AC$1:$AE$23,Daten!AB23,0) -> Berechnung der Fensterelemente
B12: =HLOOKUP(W2,Daten!$AC$1:$AE$26,Daten!AB4,0) -> Höhe - Unterkante Rinne [mm] (H3) | C12: =HLOOKUP(W2,Daten!$AC$1:$AE$22,Daten!AB5,0) -> Bestelltiefe [mm] | D12: =HLOOKUP(W2,Daten!$AC$1:$AE$26,Daten!AB6,0) -> Höhe - Unterkante Wandprofil [mm] (H1) | E12: =HLOOKUP(W2,Daten!$AC$1:$AE$26,Daten!AB25,0) -> Dachüberstand [mm] (U1) | F12: =HLOOKUP(W2,Daten!$AC$1:$AE$26,Daten!AB7,0) -> Neigung [°] (α) | G12: =HLOOKUP(W2,Daten!$AC$1:$AE$27,Daten!AB27,0) -> Neigung [mm/m] | H12: =HLOOKUP(W2,Daten!$AC$1:$AE$26,Daten!AB26,0) -> Neigung Glas Ultraline [°] (β) | I12: =HLOOKUP(W2,Daten!$AC$1:$AE$22,Daten!AB8,0) -> Tiefe - Hinterkante Wandanschluss bis Mitte Pfosten [mm] (D1) | J12: =HLOOKUP(W2,Daten!$AC$1:$AE$22,Daten!AB9,0) -> Länge - Sparren Mitte [mm] (S1) | K12: =HLOOKUP(W2,Daten!$AC$1:$AE$22,Daten!AB10,0) -> Länge - Sparren Außen [mm] (S1) | L12: =HLOOKUP(W2,Daten!$AC$1:$AE$22,Daten!AB11,0) -> Tiefe - Hinterkante Wandanschluss bis Rinne Standard [mm] (D3) | M12: =HLOOKUP(W2,Daten!$AC$1:$AE$22,Daten!AB12,0) -> Tiefe - Hinterkante Wandanschluss bis Zierleiste rund [mm] (D3) | N12: =HLOOKUP(W2,Daten!$AC$1:$AE$22,Daten!AB13,0) -> Tiefe - Hinterkante Wandanschluss bis Zierleiste klassik [mm] (D3) | O12: =HLOOKUP(W2,Daten!$AC$1:$AE$22,Daten!AB14,0) -> Tiefe - Hinterkante Wandanschluss bis Innenkante Pfosten [mm] (D2) | P12: =HLOOKUP(W2,Daten!$AC$1:$AE$22,Daten!AB15,0) -> Höhe - Oberkante Wandprofil [mm] (H2) | Q12: =HLOOKUP(W2,Daten!$AC$1:$AE$22,Daten!AB21,0) -> Hinterkante Wandanschluss bis Außenkante Pfosten [mm] (D4) | R12: =HLOOKUP(W2,Daten!$AC$1:$AE$22,Daten!AB22,0) -> Hinterkante Wandanschluss bis Außenkante Pfosten [mm] (D5) | S12: =HLOOKUP(W2,Daten!$AC$1:$AE$22,Daten!AB16,0) -> Fensterhöhe Rinnenseite [mm] | T12: =HLOOKUP(W2,Daten!$AC$1:$AE$22,Daten!AB17,0) -> Fensterbreite [mm] | U12: =HLOOKUP(W2,Daten!$AC$1:$AE$22,Daten!AB18,0) -> Keilhöhe Rinnenseite [mm] | V12: =HLOOKUP(W2,Daten!$AC$1:$AE$22,Daten!AB19,0) -> Keilhöhe Hausseite [mm] | W12: =HLOOKUP(W2,Daten!$AC$1:$AE$22,Daten!AB20,0) -> Fensterhöhe Hausseite [mm]
A17: Type
A18: Trendline | B18: 2250 | C18: 4050 | D18: 2700 | E18: =Daten!E20 -> - | F18: =Daten!F20 -> 5.841574 | G18: =Daten!G20 -> 102.30944 | H18: =Daten!H20 -> - | I18: =Daten!I20 -> 4061.3881 | J18: =Daten!J20 -> 3950 | K18: =Daten!K20 -> - | L18: =Daten!L20 -> 4173.3881 | ... O18: =Daten!O20 -> 4006.3881 | P18: =IF(U5=U6,Daten!P20,IF(U5=V6,Daten!X20,"Option Select!")) -> 2862.2 | Q18: =Daten!Q20 -> 4116.3881 | R18: =Daten!R20 -> 4233.3881 | S18: =Daten!S20 -> 2289 | T18: =Daten!T20 -> 4006.3881 | U18: =Daten!U20 -> 39 | V18: =Daten!V20 -> 450 | W18: =Daten!W20 -> 2700
L19: =U7&" "&U9 -> Zierleiste Standard | M19: =U7&" "&V9 -> Zierleiste Rund | N19: =U7&" "&W9 -> Zierleiste Klassik
A21: Gelbe Zellen manuell ausfüllen!

Sheet Trendline+
U1: =Orangeline!U1 -> 45919 | W1: TFl
U2: =HLOOKUP(W2,Daten!$AC$1:$AE$24,Daten!AB24,0) -> Sprache | W2: GER
U4: =HLOOKUP(W2,Daten!$AC$1:$AE$30,Daten!AB29,0) -> Wandprofil
U5: Standard
U6: =HLOOKUP(W2,Daten!$AC$1:$AE$30,Daten!AB30,0) -> Standard | V6: =HLOOKUP(W2,Daten!$AC$1:$AE$31,Daten!AB31,0) -> XL
B10: =IFERROR(IF(B18="-","= 0 mm","= " & TEXT(B18,"#")&" mm"),"") -> = 2250 mm | C10: =IFERROR(IF(C18="-","= 0 mm","= " & TEXT(C18,"#")&" mm"),"") -> = 4050 mm | D10: =IFERROR(IF(D18="-","= 0 mm","= " & TEXT(D18,"#")&" mm"),"") -> = 2700 mm | E10: =IFERROR(IF(E18="-","0 mm =",TEXT(E18,"#")&" mm ="),"") -> 0 mm = | F10: =IFERROR(IF(F18="-","= 0°","= " & TEXT(F18,"0,0")&"°"),"") -> = 5,7° | G10: =IFERROR(IF(G18="-","= 0 mm/m","= " & TEXT(G18,"0,0")&" mm/m"),"") -> = 99,8 mm/m | H10: =IFERROR(IF(H18="-","= 0°","= " & TEXT(H18,"0,0")&"°"),"") -> = 0° | I10: =IFERROR(IF(I18="-","= 0 mm","= " & TEXT(I18,"#")&" mm"),"") -> = 4062 mm | J10: =IFERROR(IF(J18="-","= 0 mm","= " & TEXT(J18,"#")&" mm"),"") -> = 3950 mm | K10: =IFERROR(IF(K18="-","= 0 mm","= " & TEXT(K18,"#")&" mm"),"") -> = 0 mm | L10: =IFERROR(IF(L18="-","= 0 mm","= " & TEXT(L18,"#")&" mm"),"") -> = 4174 mm | M10: =IFERROR(IF(M18="-","= 0 mm","= " & TEXT(M18,"#")&" mm"),"") -> = 0 mm | N10: =IFERROR(IF(N18="-","= 0 mm","= " & TEXT(N18,"#")&" mm"),"") -> = 0 mm | O10: =IFERROR(IF(O18="-","= 0 mm","= " & TEXT(O18,"#")&" mm"),"") -> = 4007 mm | P10: =IFERROR(IF(OR(P18="-",P18="Option select!"),"= 0 mm","= " & TEXT(P18,"#")&" mm"),"") -> = 2862 mm | Q10: =IFERROR(IF(Q18="-","= 0 mm","= " & TEXT(Q18,"#")&" mm"),"") -> = 4117 mm | R10: =IFERROR(IF(R18="-","= 0 mm","= " & TEXT(R18,"#")&" mm"),"") -> = 4234 mm | S10: =IFERROR(IF(S18="-","= 0 mm","= " & TEXT(S18,"#")&" mm"),"") -> = 2300 mm | T10: =IFERROR(IF(T18="-","= 0 mm","= " & TEXT(T18,"#")&" mm"),"") -> = 4007 mm | U10: =IFERROR(IF(U18="-","= 0 mm","= " & TEXT(U18,"#")&" mm"),"") -> = 50 mm | V10: =IFERROR(IF(V18="-","= 0 mm","= " & TEXT(V18,"#")&" mm"),"") -> = 450 mm | W10: =IFERROR(IF(W18="-","= 0 mm","= " & TEXT(W18,"#")&" mm"),"") -> = 2700 mm
A11: =HLOOKUP(W2,Daten!$AC$1:$AE$22,Daten!AB3,0) -> Berechnung der Höhe und Tiefe einer Veranda | S11: =HLOOKUP(W2,Daten!$AC$1:$AE$23,Daten!AB23,0) -> Berechnung der Fensterelemente
B12: =HLOOKUP(W2,Daten!$AC$1:$AE$26,Daten!AB4,0) -> Höhe - Unterkante Rinne [mm] (H3) | C12: =HLOOKUP(W2,Daten!$AC$1:$AE$22,Daten!AB5,0) -> Bestelltiefe [mm] | D12: =HLOOKUP(W2,Daten!$AC$1:$AE$26,Daten!AB6,0) -> Höhe - Unterkante Wandprofil [mm] (H1) | E12: =HLOOKUP(W2,Daten!$AC$1:$AE$26,Daten!AB25,0) -> Dachüberstand [mm] (U1) | F12: =HLOOKUP(W2,Daten!$AC$1:$AE$26,Daten!AB7,0) -> Neigung [°] (α) | G12: =HLOOKUP(W2,Daten!$AC$1:$AE$27,Daten!AB27,0) -> Neigung [mm/m] | H12: =HLOOKUP(W2,Daten!$AC$1:$AE$26,Daten!AB26,0) -> Neigung Glas Ultraline [°] (β) | I12: =HLOOKUP(W2,Daten!$AC$1:$AE$22,Daten!AB8,0) -> Tiefe - Hinterkante Wandanschluss bis Mitte Pfosten [mm] (D1) | J12: =HLOOKUP(W2,Daten!$AC$1:$AE$22,Daten!AB9,0) -> Länge - Sparren Mitte [mm] (S1) | K12: =HLOOKUP(W2,Daten!$AC$1:$AE$22,Daten!AB10,0) -> Länge - Sparren Außen [mm] (S1) | L12: =HLOOKUP(W2,Daten!$AC$1:$AE$22,Daten!AB11,0) -> Tiefe - Hinterkante Wandanschluss bis Rinne Standard [mm] (D3) | M12: =HLOOKUP(W2,Daten!$AC$1:$AE$22,Daten!AB12,0) -> Tiefe - Hinterkante Wandanschluss bis Zierleiste rund [mm] (D3) | N12: =HLOOKUP(W2,Daten!$AC$1:$AE$22,Daten!AB13,0) -> Tiefe - Hinterkante Wandanschluss bis Zierleiste klassik [mm] (D3) | O12: =HLOOKUP(W2,Daten!$AC$1:$AE$22,Daten!AB14,0) -> Tiefe - Hinterkante Wandanschluss bis Innenkante Pfosten [mm] (D2) | P12: =HLOOKUP(W2,Daten!$AC$1:$AE$22,Daten!AB15,0) -> Höhe - Oberkante Wandprofil [mm] (H2) | Q12: =HLOOKUP(W2,Daten!$AC$1:$AE$22,Daten!AB21,0) -> Hinterkante Wandanschluss bis Außenkante Pfosten [mm] (D4) | R12: =HLOOKUP(W2,Daten!$AC$1:$AE$22,Daten!AB22,0) -> Hinterkante Wandanschluss bis Außenkante Pfosten [mm] (D5) | S12: =HLOOKUP(W2,Daten!$AC$1:$AE$22,Daten!AB16,0) -> Fensterhöhe Rinnenseite [mm] | T12: =HLOOKUP(W2,Daten!$AC$1:$AE$22,Daten!AB17,0) -> Fensterbreite [mm] | U12: =HLOOKUP(W2,Daten!$AC$1:$AE$22,Daten!AB18,0) -> Keilhöhe Rinnenseite [mm] | V12: =HLOOKUP(W2,Daten!$AC$1:$AE$22,Daten!AB19,0) -> Keilhöhe Hausseite [mm] | W12: =HLOOKUP(W2,Daten!$AC$1:$AE$22,Daten!AB20,0) -> Fensterhöhe Hausseite [mm]
A17: Type
A18: Trendline+ | B18: 2250 | C18: 4050 | D18: 2700 | E18: =Daten!E21 -> - | F18: =Daten!F21 -> 5.696532 | G18: =Daten!G21 -> 99.752138 | H18: =Daten!H21 -> - | I18: =Daten!I21 -> 4062.2925 | J18: =Daten!J21 -> 3950 | K18: =Daten!K21 -> - | L18: =Daten!L21 -> 4174.3925 | ... O18: =Daten!O21 -> 4007.2925 | P18: =IF(U5=U6,Daten!P21,IF(U5=V6,Daten!X21,"Option Select!")) -> 2862.2 | Q18: =Daten!Q21 -> 4117.2925 | R18: =Daten!R21 -> 4234.2925 | S18: =Daten!S21 -> 2300.1 | T18: =Daten!T21 -> 4007.2925 | U18: =Daten!U21 -> 50.1 | V18: =Daten!V21 -> 450 | W18: =Daten!W21 -> 2700
A21: Gelbe Zellen manuell ausfüllen!

Sheet Topline
U1: =Orangeline!U1 -> 45919 | W1: TFl
U2: =HLOOKUP(W2,Daten!$AC$1:$AE$24,Daten!AB24,0) -> Sprache | W2: GER
U4: =HLOOKUP(W2,Daten!$AC$1:$AE$30,Daten!AB29,0) -> Wandprofil
U5: Standard
U6: =HLOOKUP(W2,Daten!$AC$1:$AE$30,Daten!AB30,0) -> Standard | V6: =HLOOKUP(W2,Daten!$AC$1:$AE$31,Daten!AB31,0) -> XL
B10: =IFERROR(IF(B18="-","= 0 mm","= " & TEXT(B18,"#")&" mm"),"") -> = 2200 mm | C10: =IFERROR(IF(C18="-","= 0 mm","= " & TEXT(C18,"#")&" mm"),"") -> = 4500 mm | D10: =IFERROR(IF(D18="-","= 0 mm","= " & TEXT(D18,"#")&" mm"),"") -> = 2700 mm | E10: =IFERROR(IF(E18="-","0 mm =",TEXT(E18,"#")&" mm ="),"") -> 0 mm = | F10: =IFERROR(IF(F18="-","= 0°","= " & TEXT(F18,"0,0")&"°"),"") -> = 5,4° | G10: =IFERROR(IF(G18="-","= 0 mm/m","= " & TEXT(G18,"0,0")&" mm/m"),"") -> = 94,0 mm/m | H10: =IFERROR(IF(H18="-","= 0°","= " & TEXT(H18,"0,0")&"°"),"") -> = 0° | I10: =IFERROR(IF(I18="-","= 0 mm","= " & TEXT(I18,"#")&" mm"),"") -> = 4479 mm | J10: =IFERROR(IF(J18="-","= 0 mm","= " & TEXT(J18,"#")&" mm"),"") -> = 4345 mm | K10: =IFERROR(IF(K18="-","= 0 mm","= " & TEXT(K18,"#")&" mm"),"") -> = 0 mm | L10: =IFERROR(IF(L18="-","= 0 mm","= " & TEXT(L18,"#")&" mm"),"") -> = 4602 mm | M10: =IFERROR(IF(M18="-","= 0 mm","= " & TEXT(M18,"#")&" mm"),"") -> = 0 mm | N10: =IFERROR(IF(N18="-","= 0 mm","= " & TEXT(N18,"#")&" mm"),"") -> = 0 mm | O10: =IFERROR(IF(O18="-","= 0 mm","= " & TEXT(O18,"#")&" mm"),"") -> = 4404 mm | P10: =IFERROR(IF(OR(P18="-",P18="Option select!"),"= 0 mm","= " & TEXT(P18,"#")&" mm"),"") -> = 2862 mm | Q10: =IFERROR(IF(Q18="-","= 0 mm","= " & TEXT(Q18,"#")&" mm"),"") -> = 4553 mm | R10: =IFERROR(IF(R18="-","= 0 mm","= " & TEXT(R18,"#")&" mm"),"") -> = 4670 mm | S10: =IFERROR(IF(S18="-","= 0 mm","= " & TEXT(S18,"#")&" mm"),"") -> = 2284 mm | T10: =IFERROR(IF(T18="-","= 0 mm","= " & TEXT(T18,"#")&" mm"),"") -> = 4404 mm | U10: =IFERROR(IF(U18="-","= 0 mm","= " & TEXT(U18,"#")&" mm"),"") -> = 84 mm | V10: =IFERROR(IF(V18="-","= 0 mm","= " & TEXT(V18,"#")&" mm"),"") -> = 500 mm | W10: =IFERROR(IF(W18="-","= 0 mm","= " & TEXT(W18,"#")&" mm"),"") -> = 2700 mm
A11: =HLOOKUP(W2,Daten!$AC$1:$AE$22,Daten!AB3,0) -> Berechnung der Höhe und Tiefe einer Veranda | S11: =HLOOKUP(W2,Daten!$AC$1:$AE$23,Daten!AB23,0) -> Berechnung der Fensterelemente
B12: =HLOOKUP(W2,Daten!$AC$1:$AE$26,Daten!AB4,0) -> Höhe - Unterkante Rinne [mm] (H3) | C12: =HLOOKUP(W2,Daten!$AC$1:$AE$22,Daten!AB5,0) -> Bestelltiefe [mm] | D12: =HLOOKUP(W2,Daten!$AC$1:$AE$26,Daten!AB6,0) -> Höhe - Unterkante Wandprofil [mm] (H1) | E12: =HLOOKUP(W2,Daten!$AC$1:$AE$26,Daten!AB25,0) -> Dachüberstand [mm] (U1) | F12: =HLOOKUP(W2,Daten!$AC$1:$AE$26,Daten!AB7,0) -> Neigung [°] (α) | G12: =HLOOKUP(W2,Daten!$AC$1:$AE$27,Daten!AB27,0) -> Neigung [mm/m] | H12: =HLOOKUP(W2,Daten!$AC$1:$AE$26,Daten!AB26,0) -> Neigung Glas Ultraline [°] (β) | I12: =HLOOKUP(W2,Daten!$AC$1:$AE$22,Daten!AB8,0) -> Tiefe - Hinterkante Wandanschluss bis Mitte Pfosten [mm] (D1) | J12: =HLOOKUP(W2,Daten!$AC$1:$AE$22,Daten!AB9,0) -> Länge - Sparren Mitte [mm] (S1) | K12: =HLOOKUP(W2,Daten!$AC$1:$AE$22,Daten!AB10,0) -> Länge - Sparren Außen [mm] (S1) | L12: =HLOOKUP(W2,Daten!$AC$1:$AE$22,Daten!AB11,0) -> Tiefe - Hinterkante Wandanschluss bis Rinne Standard [mm] (D3) | M12: =HLOOKUP(W2,Daten!$AC$1:$AE$22,Daten!AB12,0) -> Tiefe - Hinterkante Wandanschluss bis Zierleiste rund [mm] (D3) | N12: =HLOOKUP(W2,Daten!$AC$1:$AE$22,Daten!AB13,0) -> Tiefe - Hinterkante Wandanschluss bis Zierleiste klassik [mm] (D3) | O12: =HLOOKUP(W2,Daten!$AC$1:$AE$22,Daten!AB14,0) -> Tiefe - Hinterkante Wandanschluss bis Innenkante Pfosten [mm] (D2) | P12: =HLOOKUP(W2,Daten!$AC$1:$AE$22,Daten!AB15,0) -> Höhe - Oberkante Wandprofil [mm] (H2) | Q12: =HLOOKUP(W2,Daten!$AC$1:$AE$22,Daten!AB21,0) -> Hinterkante Wandanschluss bis Außenkante Pfosten [mm] (D4) | R12: =HLOOKUP(W2,Daten!$AC$1:$AE$22,Daten!AB22,0) -> Hinterkante Wandanschluss bis Außenkante Pfosten [mm] (D5) | S12: =HLOOKUP(W2,Daten!$AC$1:$AE$22,Daten!AB16,0) -> Fensterhöhe Rinnenseite [mm] | T12: =HLOOKUP(W2,Daten!$AC$1:$AE$22,Daten!AB17,0) -> Fensterbreite [mm] | U12: =HLOOKUP(W2,Daten!$AC$1:$AE$22,Daten!AB18,0) -> Keilhöhe Rinnenseite [mm] | V12: =HLOOKUP(W2,Daten!$AC$1:$AE$22,Daten!AB19,0) -> Keilhöhe Hausseite [mm] | W12: =HLOOKUP(W2,Daten!$AC$1:$AE$22,Daten!AB20,0) -> Fensterhöhe Hausseite [mm]
A17: Type
A18: Topline | B18: 2200 | C18: 4500 | D18: 2700 | E18: =Daten!E22 -> - | F18: =Daten!F22 -> 5.3680911 | G18: =Daten!G22 -> 93.965969 | H18: =Daten!H22 -> - | I18: =Daten!I22 -> 4478.5438 | J18: =Daten!J22 -> 4345 | K18: =Daten!K22 -> - | L18: =Daten!L22 -> 4601.5438 | ... O18: =Daten!O22 -> 4404.0438 | P18: =IF(U5=U6,Daten!P22,IF(U5=V6,Daten!X22,"Option Select!")) -> 2862.2 | Q18: =Daten!Q22 -> 4553.0438 | R18: =Daten!R22 -> 4670.0438 | S18: =Daten!S22 -> 2284 | T18: =Daten!T22 -> 4404.0438 | U18: =Daten!U22 -> 84 | V18: =Daten!V22 -> 500 | W18: =Daten!W22 -> 2700
A21: Gelbe Zellen manuell ausfüllen!

Sheet Topline XL
U1: =Orangeline!U1 -> 45919 | W1: TFl
U2: =HLOOKUP(W2,Daten!$AC$1:$AE$24,Daten!AB24,0) -> Sprache | W2: GER
U4: =HLOOKUP(W2,Daten!$AC$1:$AE$30,Daten!AB29,0) -> Wandprofil
U5: Standard
U6: =HLOOKUP(W2,Daten!$AC$1:$AE$30,Daten!AB30,0) -> Standard | V6: =HLOOKUP(W2,Daten!$AC$1:$AE$31,Daten!AB31,0) -> XL
B10: =IFERROR(IF(B18="-","= 0 mm","= " & TEXT(B18,"#")&" mm"),"") -> = 2200 mm | C10: =IFERROR(IF(C18="-","= 0 mm","= " & TEXT(C18,"#")&" mm"),"") -> = 4000 mm | D10: =IFERROR(IF(D18="-","= 0 mm","= " & TEXT(D18,"#")&" mm"),"") -> = 2700 mm | E10: =IFERROR(IF(E18="-","0 mm =",TEXT(E18,"#")&" mm ="),"") -> 0 mm = | F10: =IFERROR(IF(F18="-","= 0°","= " & TEXT(F18,"0,0")&"°"),"") -> = 5,7° | G10: =IFERROR(IF(G18="-","= 0 mm/m","= " & TEXT(G18,"0,0")&" mm/m"),"") -> = 100,0 mm/m | H10: =IFERROR(IF(H18="-","= 0°","= " & TEXT(H18,"0,0")&"°"),"") -> = 0° | I10: =IFERROR(IF(I18="-","= 0 mm","= " & TEXT(I18,"#")&" mm"),"") -> = 3998 mm | J10: =IFERROR(IF(J18="-","= 0 mm","= " & TEXT(J18,"#")&" mm"),"") -> = 3845 mm | K10: =IFERROR(IF(K18="-","= 0 mm","= " & TEXT(K18,"#")&" mm"),"") -> = 0 mm | L10: =IFERROR(IF(L18="-","= 0 mm","= " & TEXT(L18,"#")&" mm"),"") -> = 4133 mm | M10: =IFERROR(IF(M18="-","= 0 mm","= " & TEXT(M18,"#")&" mm"),"") -> = 0 mm | N10: =IFERROR(IF(N18="-","= 0 mm","= " & TEXT(N18,"#")&" mm"),"") -> = 0 mm | O10: =IFERROR(IF(O18="-","= 0 mm","= " & TEXT(O18,"#")&" mm"),"") -> = 3901 mm | P10: =IFERROR(IF(OR(P18="-",P18="Option select!"),"= 0 mm","= " & TEXT(P18,"#")&" mm"),"") -> = 2862 mm | Q10: =IFERROR(IF(Q18="-","= 0 mm","= " & TEXT(Q18,"#")&" mm"),"") -> = 4097 mm | R10: =IFERROR(IF(R18="-","= 0 mm","= " & TEXT(R18,"#")&" mm"),"") -> = 4214 mm | S10: =IFERROR(IF(S18="-","= 0 mm","= " & TEXT(S18,"#")&" mm"),"") -> = 2306 mm | T10: =IFERROR(IF(T18="-","= 0 mm","= " & TEXT(T18,"#")&" mm"),"") -> = 3901 mm | U10: =IFERROR(IF(U18="-","= 0 mm","= " & TEXT(U18,"#")&" mm"),"") -> = 106 mm | V10: =IFERROR(IF(V18="-","= 0 mm","= " & TEXT(V18,"#")&" mm"),"") -> = 500 mm | W10: =IFERROR(IF(W18="-","= 0 mm","= " & TEXT(W18,"#")&" mm"),"") -> = 2700 mm
A11: =HLOOKUP(W2,Daten!$AC$1:$AE$22,Daten!AB3,0) -> Berechnung der Höhe und Tiefe einer Veranda | S11: =HLOOKUP(W2,Daten!$AC$1:$AE$23,Daten!AB23,0) -> Berechnung der Fensterelemente
B12: =HLOOKUP(W2,Daten!$AC$1:$AE$26,Daten!AB4,0) -> Höhe - Unterkante Rinne [mm] (H3) | C12: =HLOOKUP(W2,Daten!$AC$1:$AE$22,Daten!AB5,0) -> Bestelltiefe [mm] | D12: =HLOOKUP(W2,Daten!$AC$1:$AE$26,Daten!AB6,0) -> Höhe - Unterkante Wandprofil [mm] (H1) | E12: =HLOOKUP(W2,Daten!$AC$1:$AE$26,Daten!AB25,0) -> Dachüberstand [mm] (U1) | F12: =HLOOKUP(W2,Daten!$AC$1:$AE$26,Daten!AB7,0) -> Neigung [°] (α) | G12: =HLOOKUP(W2,Daten!$AC$1:$AE$27,Daten!AB27,0) -> Neigung [mm/m] | H12: =HLOOKUP(W2,Daten!$AC$1:$AE$26,Daten!AB26,0) -> Neigung Glas Ultraline [°] (β) | I12: =HLOOKUP(W2,Daten!$AC$1:$AE$22,Daten!AB8,0) -> Tiefe - Hinterkante Wandanschluss bis Mitte Pfosten [mm] (D1) | J12: =HLOOKUP(W2,Daten!$AC$1:$AE$22,Daten!AB9,0) -> Länge - Sparren Mitte [mm] (S1) | K12: =HLOOKUP(W2,Daten!$AC$1:$AE$22,Daten!AB10,0) -> Länge - Sparren Außen [mm] (S1) | L12: =HLOOKUP(W2,Daten!$AC$1:$AE$22,Daten!AB11,0) -> Tiefe - Hinterkante Wandanschluss bis Rinne Standard [mm] (D3) | M12: =HLOOKUP(W2,Daten!$AC$1:$AE$22,Daten!AB12,0) -> Tiefe - Hinterkante Wandanschluss bis Zierleiste rund [mm] (D3) | N12: =HLOOKUP(W2,Daten!$AC$1:$AE$22,Daten!AB13,0) -> Tiefe - Hinterkante Wandanschluss bis Zierleiste klassik [mm] (D3) | O12: =HLOOKUP(W2,Daten!$AC$1:$AE$22,Daten!AB14,0) -> Tiefe - Hinterkante Wandanschluss bis Innenkante Pfosten [mm] (D2) | P12: =HLOOKUP(W2,Daten!$AC$1:$AE$22,Daten!AB15,0) -> Höhe - Oberkante Wandprofil [mm] (H2) | Q12: =HLOOKUP(W2,Daten!$AC$1:$AE$22,Daten!AB21,0) -> Hinterkante Wandanschluss bis Außenkante Pfosten [mm] (D4) | R12: =HLOOKUP(W2,Daten!$AC$1:$AE$22,Daten!AB22,0) -> Hinterkante Wandanschluss bis Außenkante Pfosten [mm] (D5) | S12: =HLOOKUP(W2,Daten!$AC$1:$AE$22,Daten!AB16,0) -> Fensterhöhe Rinnenseite [mm] | T12: =HLOOKUP(W2,Daten!$AC$1:$AE$22,Daten!AB17,0) -> Fensterbreite [mm] | U12: =HLOOKUP(W2,Daten!$AC$1:$AE$22,Daten!AB18,0) -> Keilhöhe Rinnenseite [mm] | V12: =HLOOKUP(W2,Daten!$AC$1:$AE$22,Daten!AB19,0) -> Keilhöhe Hausseite [mm] | W12: =HLOOKUP(W2,Daten!$AC$1:$AE$22,Daten!AB20,0) -> Fensterhöhe Hausseite [mm]
A17: Type
A18: Topline XL | B18: 2200 | C18: 4000 | D18: 2700 | E18: =Daten!E23 -> - | F18: =Daten!F23 -> 5.7102702 | G18: =Daten!G23 -> 99.994308 | H18: =Daten!H23 -> - | I18: =Daten!I23 -> 3998.3202 | J18: =Daten!J23 -> 3845 | K18: =Daten!K23 -> - | L18: =Daten!L23 -> 4133.1202 | ... O18: =Daten!O23 -> 3900.6202 | P18: =IF(U5=U6,Daten!P23,IF(U5=V6,Daten!X23,"Option Select!")) -> 2862.2 | Q18: =Daten!Q23 -> 4096.6202 | R18: =Daten!R23 -> 4213.6202 | S18: =Daten!S23 -> 2306 | T18: =Daten!T23 -> 3900.6202 | U18: =Daten!U23 -> 106 | V18: =Daten!V23 -> 500 | W18: =Daten!W23 -> 2700
A21: Gelbe Zellen manuell ausfüllen!

Sheet Designline
U1: =Orangeline!U1 -> 45919 | W1: TFl
U2: =HLOOKUP(W2,Daten!$AC$1:$AE$24,Daten!AB24,0) -> Sprache | W2: GER
B10: =IFERROR(IF(B18="-","= 0 mm","= " & TEXT(B18,"#")&" mm"),"") -> = 2250 mm | C10: =IFERROR(IF(C18="-","= 0 mm","= " & TEXT(C18,"#")&" mm"),"") -> = 4000 mm | D10: =IFERROR(IF(D18="-","= 0 mm","= " & TEXT(D18,"#")&" mm"),"") -> = 2700 mm | E10: =IFERROR(IF(E18="-","0 mm =",TEXT(E18,"#")&" mm ="),"") -> 0 mm = | F10: =IFERROR(IF(F18="-","= 0°","= " & TEXT(F18,"0,0")&"°"),"") -> = 5,4° | G10: =IFERROR(IF(G18="-","= 0 mm/m","= " & TEXT(G18,"0,0")&" mm/m"),"") -> = 94,8 mm/m | H10: =IFERROR(IF(H18="-","= 0°","= " & TEXT(H18,"0,0")&"°"),"") -> = 0° | I10: =IFERROR(IF(I18="-","= 0 mm","= " & TEXT(I18,"#")&" mm"),"") -> = 4031 mm | J10: =IFERROR(IF(J18="-","= 0 mm","= " & TEXT(J18,"#")&" mm"),"") -> = 4005 mm | K10: =IFERROR(IF(K18="-","= 0 mm","= " & TEXT(K18,"#")&" mm"),"") -> = 0 mm | L10: =IFERROR(IF(L18="-","= 0 mm","= " & TEXT(L18,"#")&" mm"),"") -> = 4145 mm | M10: =IFERROR(IF(M18="-","= 0 mm","= " & TEXT(M18,"#")&" mm"),"") -> = 0 mm | N10: =IFERROR(IF(N18="-","= 0 mm","= " & TEXT(N18,"#")&" mm"),"") -> = 0 mm | O10: =IFERROR(IF(O18="-","= 0 mm","= " & TEXT(O18,"#")&" mm"),"") -> = 3933 mm | P10: =IFERROR(IF(P18="-","= 0 mm","= " & TEXT(P18,"#")&" mm"),"") -> = 2864 mm | ... W10: =IFERROR(IF(W18="-","= 0 mm","= " & TEXT(W18,"#")&" mm"),"") -> = 2700 mm
A11: =HLOOKUP(W2,Daten!$AC$1:$AE$22,Daten!AB3,0) -> Berechnung der Höhe und Tiefe einer Veranda | S11: =HLOOKUP(W2,Daten!$AC$1:$AE$23,Daten!AB23,0) -> Berechnung der Fensterelemente
B12: =HLOOKUP(W2,Daten!$AC$1:$AE$26,Daten!AB4,0) -> Höhe - Unterkante Rinne [mm] (H3) | C12: =HLOOKUP(W2,Daten!$AC$1:$AE$22,Daten!AB5,0) -> Bestelltiefe [mm] | D12: =HLOOKUP(W2,Daten!$AC$1:$AE$26,Daten!AB6,0) -> Höhe - Unterkante Wandprofil [mm] (H1) | E12: =HLOOKUP(W2,Daten!$AC$1:$AE$26,Daten!AB25,0) -> Dachüberstand [mm] (U1) | F12: =HLOOKUP(W2,Daten!$AC$1:$AE$26,Daten!AB7,0) -> Neigung [°] (α) | G12: =HLOOKUP(W2,Daten!$AC$1:$AE$27,Daten!AB27,0) -> Neigung [mm/m] | H12: =HLOOKUP(W2,Daten!$AC$1:$AE$26,Daten!AB26,0) -> Neigung Glas Ultraline [°] (β) | I12: =HLOOKUP(W2,Daten!$AC$1:$AE$22,Daten!AB8,0) -> Tiefe - Hinterkante Wandanschluss bis Mitte Pfosten [mm] (D1) | J12: =HLOOKUP(W2,Daten!$AC$1:$AE$22,Daten!AB9,0) -> Länge - Sparren Mitte [mm] (S1) | K12: =HLOOKUP(W2,Daten!$AC$1:$AE$22,Daten!AB10,0) -> Länge - Sparren Außen [mm] (S1) | L12: =HLOOKUP(W2,Daten!$AC$1:$AE$22,Daten!AB11,0) -> Tiefe - Hinterkante Wandanschluss bis Rinne Standard [mm] (D3) | M12: =HLOOKUP(W2,Daten!$AC$1:$AE$22,Daten!AB12,0) -> Tiefe - Hinterkante Wandanschluss bis Zierleiste rund [mm] (D3) | N12: =HLOOKUP(W2,Daten!$AC$1:$AE$22,Daten!AB13,0) -> Tiefe - Hinterkante Wandanschluss bis Zierleiste klassik [mm] (D3) | O12: =HLOOKUP(W2,Daten!$AC$1:$AE$22,Daten!AB14,0) -> Tiefe - Hinterkante Wandanschluss bis Innenkante Pfosten [mm] (D2) | P12: =HLOOKUP(W2,Daten!$AC$1:$AE$22,Daten!AB15,0) -> Höhe - Oberkante Wandprofil [mm] (H2) | Q12: =HLOOKUP(W2,Daten!$AC$1:$AE$22,Daten!AB21,0) -> Hinterkante Wandanschluss bis Außenkante Pfosten [mm] (D4) | R12: =HLOOKUP(W2,Daten!$AC$1:$AE$22,Daten!AB22,0) -> Hinterkante Wandanschluss bis Außenkante Pfosten [mm] (D5) | S12: =HLOOKUP(W2,Daten!$AC$1:$AE$22,Daten!AB16,0) -> Fensterhöhe Rinnenseite [mm] | T12: =HLOOKUP(W2,Daten!$AC$1:$AE$22,Daten!AB17,0) -> Fensterbreite [mm] | U12: =HLOOKUP(W2,Daten!$AC$1:$AE$22,Daten!AB18,0) -> Keilhöhe Rinnenseite [mm] | V12: =HLOOKUP(W2,Daten!$AC$1:$AE$22,Daten!AB19,0) -> Keilhöhe Hausseite [mm] | W12: =HLOOKUP(W2,Daten!$AC$1:$AE$22,Daten!AB20,0) -> Fensterhöhe Hausseite [mm]
A17: Type
A18: Designline | B18: 2250 | C18: 4000 | D18: 2700 | E18: =Daten!E24 -> - | F18: =Daten!F24 -> 5.4167639 | G18: =Daten!G24 -> 94.823039 | H18: =Daten!H24 -> - | I18: =Daten!I24 -> 4030.5983 | J18: =Daten!J24 -> 4005 | K18: =Daten!K24 -> - | L18: =Daten!L24 -> 4145.0983 | ... W18: =Daten!W24 -> 2700
A21: Gelbe Zellen manuell ausfüllen!

Sheet Ultraline Classic
U1: =Orangeline!U1 -> 45919 | W1: TFl
U2: =HLOOKUP(W2,Daten!$AC$1:$AE$24,Daten!AB24,0) -> Sprache | W2: GER
B10: =IFERROR(IF(B18="-","= 0 mm","= " & TEXT(B18,"#")&" mm"),"") -> = 2067 mm | C10: =IFERROR(IF(C18="-","= 0 mm","= " & TEXT(C18,"#")&" mm"),"") -> = 4000 mm | D10: =IFERROR(IF(D18="-","= 0 mm","= " & TEXT(D18,"#")&" mm"),"") -> = 2285 mm | E10: =IFERROR(IF(E18="-","0 mm =",TEXT(E18,"#")&" mm ="),"") -> 500 mm = | F10: =IFERROR(IF(F18="-","= 0°","= " & TEXT(F18,"0,0")&"°"),"") -> = 0° | G10: =IFERROR(IF(G18="-","= 0 mm/m","= " & TEXT(G18,"0,0")&" mm/m"),"") -> = 0 mm/m | H10: =IFERROR(IF(H18="-","= 0°","= " & TEXT(H18,"0,0")&"°"),"") -> = 2,6° | I10: =IFERROR(IF(I18="-","= 0 mm","= " & TEXT(I18,"#")&" mm"),"") -> = 3400 mm | J10: =IFERROR(IF(J18="-","= 0 mm","= " & TEXT(J18,"#")&" mm"),"") -> = 3880 mm | K10: =IFERROR(IF(K18="-","= 0 mm","= " & TEXT(K18,"#")&" mm"),"") -> = 0 mm | L10: =IFERROR(IF(L18="-","= 0 mm","= " & TEXT(L18,"#")&" mm"),"") -> = 3500 mm | M10: =IFERROR(IF(M18="-","= 0 mm","= " & TEXT(M18,"#")&" mm"),"") -> = 0 mm | N10: =IFERROR(IF(N18="-","= 0 mm","= " & TEXT(N18,"#")&" mm"),"") -> = 0 mm | O10: =IFERROR(IF(O18="-","= 0 mm","= " & TEXT(O18,"#")&" mm"),"") -> = 3302 mm | P10: =IFERROR(IF(P18="-","= 0 mm","= " & TEXT(P18,"#")&" mm"),"") -> = 2525 mm | ... W10: =IFERROR(IF(W18="-","= 0 mm","= " & TEXT(W18,"#")&" mm"),"") -> = 2287 mm
A11: =HLOOKUP(W2,Daten!$AC$1:$AE$22,Daten!AB3,0) -> Berechnung der Höhe und Tiefe einer Veranda | S11: =HLOOKUP(W2,Daten!$AC$1:$AE$23,Daten!AB23,0) -> Berechnung der Fensterelemente
B12: =HLOOKUP(W2,Daten!$AC$1:$AE$26,Daten!AB4,0) -> Höhe - Unterkante Rinne [mm] (H3) | C12: =HLOOKUP(W2,Daten!$AC$1:$AE$22,Daten!AB5,0) -> Bestelltiefe [mm] | D12: =HLOOKUP(W2,Daten!$AC$1:$AE$26,Daten!AB6,0) -> Höhe - Unterkante Wandprofil [mm] (H1) | E12: =HLOOKUP(W2,Daten!$AC$1:$AE$26,Daten!AB25,0) -> Dachüberstand [mm] (U1) | F12: =HLOOKUP(W2,Daten!$AC$1:$AE$26,Daten!AB7,0) -> Neigung [°] (α) | G12: =HLOOKUP(W2,Daten!$AC$1:$AE$27,Daten!AB27,0) -> Neigung [mm/m] | H12: =HLOOKUP(W2,Daten!$AC$1:$AE$26,Daten!AB26,0) -> Neigung Glas Ultraline [°] (β) | I12: =HLOOKUP(W2,Daten!$AC$1:$AE$22,Daten!AB8,0) -> Tiefe - Hinterkante Wandanschluss bis Mitte Pfosten [mm] (D1) | J12: =HLOOKUP(W2,Daten!$AC$1:$AE$22,Daten!AB9,0) -> Länge - Sparren Mitte [mm] (S1) | K12: =HLOOKUP(W2,Daten!$AC$1:$AE$22,Daten!AB10,0) -> Länge - Sparren Außen [mm] (S1) | L12: =HLOOKUP(W2,Daten!$AC$1:$AE$22,Daten!AB11,0) -> Tiefe - Hinterkante Wandanschluss bis Rinne Standard [mm] (D3) | M12: =HLOOKUP(W2,Daten!$AC$1:$AE$22,Daten!AB12,0) -> Tiefe - Hinterkante Wandanschluss bis Zierleiste rund [mm] (D3) | N12: =HLOOKUP(W2,Daten!$AC$1:$AE$22,Daten!AB13,0) -> Tiefe - Hinterkante Wandanschluss bis Zierleiste klassik [mm] (D3) | O12: =HLOOKUP(W2,Daten!$AC$1:$AE$22,Daten!AB14,0) -> Tiefe - Hinterkante Wandanschluss bis Innenkante Pfosten [mm] (D2) | P12: =HLOOKUP(W2,Daten!$AC$1:$AE$22,Daten!AB15,0) -> Höhe - Oberkante Wandprofil [mm] (H2) | Q12: =HLOOKUP(W2,Daten!$AC$1:$AE$22,Daten!AB21,0) -> Hinterkante Wandanschluss bis Außenkante Pfosten [mm] (D4) | R12: =HLOOKUP(W2,Daten!$AC$1:$AE$22,Daten!AB22,0) -> Hinterkante Wandanschluss bis Außenkante Pfosten [mm] (D5) | S12: =HLOOKUP(W2,Daten!$AC$1:$AE$22,Daten!AB16,0) -> Fensterhöhe Rinnenseite [mm] | T12: =HLOOKUP(W2,Daten!$AC$1:$AE$22,Daten!AB17,0) -> Fensterbreite [mm] | U12: =HLOOKUP(W2,Daten!$AC$1:$AE$22,Daten!AB18,0) -> Keilhöhe Rinnenseite [mm] | V12: =HLOOKUP(W2,Daten!$AC$1:$AE$22,Daten!AB19,0) -> Keilhöhe Hausseite [mm] | W12: =HLOOKUP(W2,Daten!$AC$1:$AE$22,Daten!AB20,0) -> Fensterhöhe Hausseite [mm]
A17: Type
A18: Ultraline Classic | B18: =Daten!B25 -> 2066.5 | C18: 4000 | D18: 2285 | E18: 500 | F18: =Daten!F25 -> - | G18: =Daten!G25 -> - | H18: =Daten!H25 -> 2.6430686 | I18: =Daten!I25 -> 3400 | J18: =Daten!J25 -> 3880 | K18: =Daten!K25 -> - | L18: =Daten!L25 -> 3500 | M18: =Daten!M25 -> - | ... W18: =Daten!W25 -> 2286.5
A21: Gelbe Zellen manuell ausfüllen!

Sheet Ultraline Style
U1: =Orangeline!U1 -> 45919 | W1: TFl
U2: =HLOOKUP(W2,Daten!$AC$1:$AE$24,Daten!AB24,0) -> Sprache | W2: GER
B10: =IFERROR(IF(B18="-","= 0 mm","= " & TEXT(B18,"#")&" mm"),"") -> = 2242 mm | C10: =IFERROR(IF(C18="-","= 0 mm","= " & TEXT(C18,"#")&" mm"),"") -> = 4306 mm | D10: =IFERROR(IF(D18="-","= 0 mm","= " & TEXT(D18,"#")&" mm"),"") -> = 2461 mm | E10: =IFERROR(IF(E18="-","0 mm =",TEXT(E18,"#")&" mm ="),"") -> 120 mm = | F10: =IFERROR(IF(F18="-","= 0°","= " & TEXT(F18,"0,0")&"°"),"") -> = 0° | G10: =IFERROR(IF(G18="-","= 0 mm/m","= " & TEXT(G18,"0,0")&" mm/m"),"") -> = 0 mm/m | H10: =IFERROR(IF(H18="-","= 0°","= " & TEXT(H18,"0,0")&"°"),"") -> = 2,1° | I10: =IFERROR(IF(I18="-","= 0 mm","= " & TEXT(I18,"#")&" mm"),"") -> = 4206 mm | J10: =IFERROR(IF(J18="-","= 0 mm","= " & TEXT(J18,"#")&" mm"),"") -> = 4306 mm | K10: =IFERROR(IF(K18="-","= 0 mm","= " & TEXT(K18,"#")&" mm"),"") -> = 0 mm | L10: =IFERROR(IF(L18="-","= 0 mm","= " & TEXT(L18,"#")&" mm"),"") -> = 4306 mm | M10: =IFERROR(IF(M18="-","= 0 mm","= " & TEXT(M18,"#")&" mm"),"") -> = 0 mm | N10: =IFERROR(IF(N18="-","= 0 mm","= " & TEXT(N18,"#")&" mm"),"") -> = 0 mm | O10: =IFERROR(IF(O18="-","= 0 mm","= " & TEXT(O18,"#")&" mm"),"") -> = 4108 mm | P10: =IFERROR(IF(P18="-","= 0 mm","= " & TEXT(P18,"#")&" mm"),"") -> = 2700 mm | ... W10: =IFERROR(IF(W18="-","= 0 mm","= " & TEXT(W18,"#")&" mm"),"") -> = 2462 mm
A11: =HLOOKUP(W2,Daten!$AC$1:$AE$22,Daten!AB3,0) -> Berechnung der Höhe und Tiefe einer Veranda | S11: =HLOOKUP(W2,Daten!$AC$1:$AE$23,Daten!AB23,0) -> Berechnung der Fensterelemente
B12: =HLOOKUP(W2,Daten!$AC$1:$AE$26,Daten!AB4,0) -> Höhe - Unterkante Rinne [mm] (H3) | C12: =HLOOKUP(W2,Daten!$AC$1:$AE$22,Daten!AB5,0) -> Bestelltiefe [mm] | D12: =HLOOKUP(W2,Daten!$AC$1:$AE$26,Daten!AB6,0) -> Höhe - Unterkante Wandprofil [mm] (H1) | E12: =HLOOKUP(W2,Daten!$AC$1:$AE$26,Daten!AB25,0) -> Dachüberstand [mm] (U1) | F12: =HLOOKUP(W2,Daten!$AC$1:$AE$26,Daten!AB7,0) -> Neigung [°] (α) | G12: =HLOOKUP(W2,Daten!$AC$1:$AE$27,Daten!AB27,0) -> Neigung [mm/m] | H12: =HLOOKUP(W2,Daten!$AC$1:$AE$26,Daten!AB26,0) -> Neigung Glas Ultraline [°] (β) | I12: =HLOOKUP(W2,Daten!$AC$1:$AE$22,Daten!AB8,0) -> Tiefe - Hinterkante Wandanschluss bis Mitte Pfosten [mm] (D1) | J12: =HLOOKUP(W2,Daten!$AC$1:$AE$22,Daten!AB9,0) -> Länge - Sparren Mitte [mm] (S1) | K12: =HLOOKUP(W2,Daten!$AC$1:$AE$22,Daten!AB10,0) -> Länge - Sparren Außen [mm] (S1) | L12: =HLOOKUP(W2,Daten!$AC$1:$AE$22,Daten!AB11,0) -> Tiefe - Hinterkante Wandanschluss bis Rinne Standard [mm] (D3) | M12: =HLOOKUP(W2,Daten!$AC$1:$AE$22,Daten!AB12,0) -> Tiefe - Hinterkante Wandanschluss bis Zierleiste rund [mm] (D3) | N12: =HLOOKUP(W2,Daten!$AC$1:$AE$22,Daten!AB13,0) -> Tiefe - Hinterkante Wandanschluss bis Zierleiste klassik [mm] (D3) | O12: =HLOOKUP(W2,Daten!$AC$1:$AE$22,Daten!AB14,0) -> Tiefe - Hinterkante Wandanschluss bis Innenkante Pfosten [mm] (D2) | P12: =HLOOKUP(W2,Daten!$AC$1:$AE$22,Daten!AB15,0) -> Höhe - Oberkante Wandprofil [mm] (H2) | Q12: =HLOOKUP(W2,Daten!$AC$1:$AE$22,Daten!AB21,0) -> Hinterkante Wandanschluss bis Außenkante Pfosten [mm] (D4) | R12: =HLOOKUP(W2,Daten!$AC$1:$AE$22,Daten!AB22,0) -> Hinterkante Wandanschluss bis Außenkante Pfosten [mm] (D5) | S12: =HLOOKUP(W2,Daten!$AC$1:$AE$22,Daten!AB16,0) -> Fensterhöhe Rinnenseite [mm] | T12: =HLOOKUP(W2,Daten!$AC$1:$AE$22,Daten!AB17,0) -> Fensterbreite [mm] | U12: =HLOOKUP(W2,Daten!$AC$1:$AE$22,Daten!AB18,0) -> Keilhöhe Rinnenseite [mm] | V12: =HLOOKUP(W2,Daten!$AC$1:$AE$22,Daten!AB19,0) -> Keilhöhe Hausseite [mm] | W12: =HLOOKUP(W2,Daten!$AC$1:$AE$22,Daten!AB20,0) -> Fensterhöhe Hausseite [mm]
A17: Type
A18: Ultraline Style | B18: =Daten!B26 -> 2242 | C18: 4306 | D18: 2460.5 | E18: =Daten!E26 -> 120 | F18: =Daten!F26 -> - | G18: =Daten!G26 -> - | H18: =Daten!H26 -> 2.1324853 | I18: =Daten!I26 -> 4206 | J18: =Daten!J26 -> 4306 | K18: =Daten!K26 -> - | L18: =Daten!L26 -> 4306 | ... W18: =Daten!W26 -> 2462
A21: Gelbe Zellen manuell ausfüllen!

Sheet Ultraline Compact
U1: =Orangeline!U1 -> 45919 | W1: TFl
U2: =HLOOKUP(W2,Daten!$AC$1:$AE$24,Daten!AB24,0) -> Sprache | W2: GER
B10: =IFERROR(IF(B18="-","= 0 mm","= " & TEXT(B18,"#")&" mm"),"") -> = 2182 mm | C10: =IFERROR(IF(C18="-","= 0 mm","= " & TEXT(C18,"#")&" mm"),"") -> = 4000 mm | D10: =IFERROR(IF(D18="-","= 0 mm","= " & TEXT(D18,"#")&" mm"),"") -> = 2400 mm | E10: =IFERROR(IF(E18="-","0 mm =",TEXT(E18,"#")&" mm ="),"") -> 0 mm = | F10: =IFERROR(IF(F18="-","= 0°","= " & TEXT(F18,"0,0")&"°"),"") -> = 0° | G10: =IFERROR(IF(G18="-","= 0 mm/m","= " & TEXT(G18,"0,0")&" mm/m"),"") -> = 0 mm/m | H10: =IFERROR(IF(H18="-","= 0°","= " & TEXT(H18,"0,0")&"°"),"") -> = 2,3° | I10: =IFERROR(IF(I18="-","= 0 mm","= " & TEXT(I18,"#")&" mm"),"") -> = 3900 mm | J10: =IFERROR(IF(J18="-","= 0 mm","= " & TEXT(J18,"#")&" mm"),"") -> = 3880 mm | K10: =IFERROR(IF(K18="-","= 0 mm","= " & TEXT(K18,"#")&" mm"),"") -> = 4000 mm | L10: =IFERROR(IF(L18="-","= 0 mm","= " & TEXT(L18,"#")&" mm"),"") -> = 4000 mm | M10: =IFERROR(IF(M18="-","= 0 mm","= " & TEXT(M18,"#")&" mm"),"") -> = 0 mm | N10: =IFERROR(IF(N18="-","= 0 mm","= " & TEXT(N18,"#")&" mm"),"") -> = 0 mm | O10: =IFERROR(IF(O18="-","= 0 mm","= " & TEXT(O18,"#")&" mm"),"") -> = 3802 mm | P10: =IFERROR(IF(P18="-","= 0 mm","= " & TEXT(P18,"#")&" mm"),"") -> = 2640 mm | ... W10: =IFERROR(IF(W18="-","= 0 mm","= " & TEXT(W18,"#")&" mm"),"") -> = 2402 mm
A11: =HLOOKUP(W2,Daten!$AC$1:$AE$22,Daten!AB3,0) -> Berechnung der Höhe und Tiefe einer Veranda | S11: =HLOOKUP(W2,Daten!$AC$1:$AE$23,Daten!AB23,0) -> Berechnung der Fensterelemente
B12: =HLOOKUP(W2,Daten!$AC$1:$AE$26,Daten!AB4,0) -> Höhe - Unterkante Rinne [mm] (H3) | C12: =HLOOKUP(W2,Daten!$AC$1:$AE$22,Daten!AB5,0) -> Bestelltiefe [mm] | D12: =HLOOKUP(W2,Daten!$AC$1:$AE$26,Daten!AB6,0) -> Höhe - Unterkante Wandprofil [mm] (H1) | E12: =HLOOKUP(W2,Daten!$AC$1:$AE$26,Daten!AB25,0) -> Dachüberstand [mm] (U1) | F12: =HLOOKUP(W2,Daten!$AC$1:$AE$26,Daten!AB7,0) -> Neigung [°] (α) | G12: =HLOOKUP(W2,Daten!$AC$1:$AE$27,Daten!AB27,0) -> Neigung [mm/m] | H12: =HLOOKUP(W2,Daten!$AC$1:$AE$26,Daten!AB26,0) -> Neigung Glas Ultraline [°] (β) | I12: =HLOOKUP(W2,Daten!$AC$1:$AE$22,Daten!AB8,0) -> Tiefe - Hinterkante Wandanschluss bis Mitte Pfosten [mm] (D1) | J12: =HLOOKUP(W2,Daten!$AC$1:$AE$22,Daten!AB9,0) -> Länge - Sparren Mitte [mm] (S1) | K12: =HLOOKUP(W2,Daten!$AC$1:$AE$22,Daten!AB10,0) -> Länge - Sparren Außen [mm] (S1) | L12: =HLOOKUP(W2,Daten!$AC$1:$AE$22,Daten!AB11,0) -> Tiefe - Hinterkante Wandanschluss bis Rinne Standard [mm] (D3) | M12: =HLOOKUP(W2,Daten!$AC$1:$AE$22,Daten!AB12,0) -> Tiefe - Hinterkante Wandanschluss bis Zierleiste rund [mm] (D3) | N12: =HLOOKUP(W2,Daten!$AC$1:$AE$22,Daten!AB13,0) -> Tiefe - Hinterkante Wandanschluss bis Zierleiste klassik [mm] (D3) | O12: =HLOOKUP(W2,Daten!$AC$1:$AE$22,Daten!AB14,0) -> Tiefe - Hinterkante Wandanschluss bis Innenkante Pfosten [mm] (D2) | P12: =HLOOKUP(W2,Daten!$AC$1:$AE$22,Daten!AB15,0) -> Höhe - Oberkante Wandprofil [mm] (H2) | Q12: =HLOOKUP(W2,Daten!$AC$1:$AE$22,Daten!AB21,0) -> Hinterkante Wandanschluss bis Außenkante Pfosten [mm] (D4) | R12: =HLOOKUP(W2,Daten!$AC$1:$AE$22,Daten!AB22,0) -> Hinterkante Wandanschluss bis Außenkante Pfosten [mm] (D5) | S12: =HLOOKUP(W2,Daten!$AC$1:$AE$22,Daten!AB16,0) -> Fensterhöhe Rinnenseite [mm] | T12: =HLOOKUP(W2,Daten!$AC$1:$AE$22,Daten!AB17,0) -> Fensterbreite [mm] | U12: =HLOOKUP(W2,Daten!$AC$1:$AE$22,Daten!AB18,0) -> Keilhöhe Rinnenseite [mm] | V12: =HLOOKUP(W2,Daten!$AC$1:$AE$22,Daten!AB19,0) -> Keilhöhe Hausseite [mm] | W12: =HLOOKUP(W2,Daten!$AC$1:$AE$22,Daten!AB20,0) -> Fensterhöhe Hausseite [mm]
A17: Type
A18: Ultraline Compact | B18: =Daten!B27 -> 2181.5 | C18: 4000 | D18: 2400 | E18: =Daten!E27 -> - | F18: =Daten!F27 -> - | G18: =Daten!G27 -> - | H18: =Daten!H27 -> 2.3012747 | I18: =Daten!I27 -> 3900 | J18: =Daten!J27 -> 3880 | K18: =Daten!K27 -> 4000 | L18: =Daten!L27 -> 4000 | ... W18: =Daten!W27 -> 2401.5
A21: Gelbe Zellen manuell ausfüllen!

Sheet Skyline
U1: =Orangeline!U1 -> 45919 | W1: TFl
U2: =HLOOKUP(W2,Daten!$AC$1:$AE$24,Daten!AB24,0) -> Sprache | W2: GER
B10: =IFERROR(IF(B18="-","= 0 mm","= " & TEXT(B18,"#")&" mm"),"") -> = 2300 mm | C10: =IFERROR(IF(C18="-","= 0 mm","= " & TEXT(C18,"#")&" mm"),"") -> = 5000 mm | D10: =IFERROR(IF(D18="-","= 0 mm","= " & TEXT(D18,"#")&" mm"),"") -> = 2300 mm | E10: =IFERROR(IF(E18="-","0 mm =",TEXT(E18,"#")&" mm ="),"") -> 0 mm = | F10: =IFERROR(IF(F18="-","= 0°","= " & TEXT(F18,"0,0")&"°"),"") -> = 0° | G10: =IFERROR(IF(G18="-","= 0 mm/m","= " & TEXT(G18,"0,0")&" mm/m"),"") -> = 0 mm/m | H10: =IFERROR(IF(H18="-","= 0°","= " & TEXT(H18,"0,0")&"°"),"") -> = 1,1° | I10: =IFERROR(IF(I18="-","= 0 mm","= " & TEXT(I18,"#")&" mm"),"") -> = 4920 mm | J10: =IFERROR(IF(J18="-","= 0 mm","= " & TEXT(J18,"#")&" mm"),"") -> = 4916 mm | K10: =IFERROR(IF(K18="-","= 0 mm","= " & TEXT(K18,"#")&" mm"),"") -> = 4916 mm | L10: =IFERROR(IF(L18="-","= 0 mm","= " & TEXT(L18,"#")&" mm"),"") -> = 5000 mm | M10: =IFERROR(IF(M18="-","= 0 mm","= " & TEXT(M18,"#")&" mm"),"") -> = 0 mm | N10: =IFERROR(IF(N18="-","= 0 mm","= " & TEXT(N18,"#")&" mm"),"") -> = 0 mm | O10: =IFERROR(IF(O18="-","= 0 mm","= " & TEXT(O18,"#")&" mm"),"") -> = 4840 mm | P10: =IFERROR(IF(P18="-","= 0 mm","= " & TEXT(P18,"#")&" mm"),"") -> = 2542 mm | ... W10: =IFERROR(IF(W18="-","= 0 mm","= " & TEXT(W18,"#")&" mm"),"") -> = 2300 mm
A11: =HLOOKUP(W2,Daten!$AC$1:$AE$22,Daten!AB3,0) -> Berechnung der Höhe und Tiefe einer Veranda | S11: =HLOOKUP(W2,Daten!$AC$1:$AE$23,Daten!AB23,0) -> Berechnung der Fensterelemente
B12: =HLOOKUP(W2,Daten!$AC$1:$AE$26,Daten!AB4,0) -> Höhe - Unterkante Rinne [mm] (H3) | C12: =HLOOKUP(W2,Daten!$AC$1:$AE$22,Daten!AB5,0) -> Bestelltiefe [mm] | D12: =HLOOKUP(W2,Daten!$AC$1:$AE$26,Daten!AB6,0) -> Höhe - Unterkante Wandprofil [mm] (H1) | E12: =HLOOKUP(W2,Daten!$AC$1:$AE$26,Daten!AB25,0) -> Dachüberstand [mm] (U1) | F12: =HLOOKUP(W2,Daten!$AC$1:$AE$26,Daten!AB7,0) -> Neigung [°] (α) | G12: =HLOOKUP(W2,Daten!$AC$1:$AE$27,Daten!AB27,0) -> Neigung [mm/m] | H12: =HLOOKUP(W2,Daten!$AC$1:$AE$26,Daten!AB26,0) -> Neigung Glas Ultraline [°] (β) | I12: =HLOOKUP(W2,Daten!$AC$1:$AE$22,Daten!AB8,0) -> Tiefe - Hinterkante Wandanschluss bis Mitte Pfosten [mm] (D1) | J12: =HLOOKUP(W2,Daten!$AC$1:$AE$22,Daten!AB9,0) -> Länge - Sparren Mitte [mm] (S1) | K12: =HLOOKUP(W2,Daten!$AC$1:$AE$22,Daten!AB10,0) -> Länge - Sparren Außen [mm] (S1) | L12: =HLOOKUP(W2,Daten!$AC$1:$AE$22,Daten!AB11,0) -> Tiefe - Hinterkante Wandanschluss bis Rinne Standard [mm] (D3) | M12: =HLOOKUP(W2,Daten!$AC$1:$AE$22,Daten!AB12,0) -> Tiefe - Hinterkante Wandanschluss bis Zierleiste rund [mm] (D3) | N12: =HLOOKUP(W2,Daten!$AC$1:$AE$22,Daten!AB13,0) -> Tiefe - Hinterkante Wandanschluss bis Zierleiste klassik [mm] (D3) | O12: =HLOOKUP(W2,Daten!$AC$1:$AE$22,Daten!AB14,0) -> Tiefe - Hinterkante Wandanschluss bis Innenkante Pfosten [mm] (D2) | P12: =HLOOKUP(W2,Daten!$AC$1:$AE$22,Daten!AB15,0) -> Höhe - Oberkante Wandprofil [mm] (H2) | Q12: =HLOOKUP(W2,Daten!$AC$1:$AE$22,Daten!AB21,0) -> Hinterkante Wandanschluss bis Außenkante Pfosten [mm] (D4) | R12: =HLOOKUP(W2,Daten!$AC$1:$AE$22,Daten!AB22,0) -> Hinterkante Wandanschluss bis Außenkante Pfosten [mm] (D5) | S12: =HLOOKUP(W2,Daten!$AC$1:$AE$22,Daten!AB16,0) -> Fensterhöhe Rinnenseite [mm] | T12: =HLOOKUP(W2,Daten!$AC$1:$AE$22,Daten!AB17,0) -> Fensterbreite [mm] | U12: =HLOOKUP(W2,Daten!$AC$1:$AE$22,Daten!AB18,0) -> Keilhöhe Rinnenseite [mm] | V12: =HLOOKUP(W2,Daten!$AC$1:$AE$22,Daten!AB19,0) -> Keilhöhe Hausseite [mm] | W12: =HLOOKUP(W2,Daten!$AC$1:$AE$22,Daten!AB20,0) -> Fensterhöhe Hausseite [mm]
A17: Type
A18: Skyline | B18: 2300 | C18: 5000 | D18: =Daten!D28 -> 2300 | E18: =Daten!E28 -> - | F18: =Daten!F28 -> - | G18: =Daten!G28 -> - | H18: =Daten!H28 -> 1.1298305 | I18: =Daten!I28 -> 4920 | J18: =Daten!J28 -> 4916 | K18: =Daten!K28 -> 4916 | ... W18: =Daten!W28 -> 2300
A21: Gelbe Zellen manuell ausfüllen!

Sheet Skyline Freistand
U1: =Orangeline!U1 -> 45919 | W1: TFl
U2: =HLOOKUP(W2,Daten!$AC$1:$AE$24,Daten!AB24,0) -> Sprache | W2: GER
B10: =IFERROR(IF(B18="-","= 0 mm","= " & TEXT(B18,"#")&" mm"),"") -> = 2300 mm | C10: =IFERROR(IF(C18="-","= 0 mm","= " & TEXT(C18,"#")&" mm"),"") -> = 5000 mm | D10: =IFERROR(IF(D18="-","= 0 mm","= " & TEXT(D18,"#")&" mm"),"") -> = 2300 mm | E10: =IFERROR(IF(E18="-","0 mm =",TEXT(E18,"#")&" mm ="),"") -> 0 mm = | F10: =IFERROR(IF(F18="-","= 0°","= " & TEXT(F18,"0,0")&"°"),"") -> = 0° | G10: =IFERROR(IF(G18="-","= 0 mm/m","= " & TEXT(G18,"0,0")&" mm/m"),"") -> = 0 mm/m | H10: =IFERROR(IF(H18="-","= 0°","= " & TEXT(H18,"0,0")&"°"),"") -> = 1,1° | I10: =IFERROR(IF(I18="-","= 0 mm","= " & TEXT(I18,"#")&" mm"),"") -> = 4760 mm | J10: =IFERROR(IF(J18="-","= 0 mm","= " & TEXT(J18,"#")&" mm"),"") -> = 4874 mm | K10: =IFERROR(IF(K18="-","= 0 mm","= " & TEXT(K18,"#")&" mm"),"") -> = 4874 mm | L10: =IFERROR(IF(L18="-","= 0 mm","= " & TEXT(L18,"#")&" mm"),"") -> = 4840 mm | M10: =IFERROR(IF(M18="-","= 0 mm","= " & TEXT(M18,"#")&" mm"),"") -> = 0 mm | N10: =IFERROR(IF(N18="-","= 0 mm","= " & TEXT(N18,"#")&" mm"),"") -> = 0 mm | O10: =IFERROR(IF(O18="-","= 0 mm","= " & TEXT(O18,"#")&" mm"),"") -> = 4680 mm | P10: =IFERROR(IF(P18="-","= 0 mm","= " & TEXT(P18,"#")&" mm"),"") -> = 2542 mm | ... W10: =IFERROR(IF(W18="-","= 0 mm","= " & TEXT(W18,"#")&" mm"),"") -> = 2300 mm
A11: =HLOOKUP(W2,Daten!$AC$1:$AE$22,Daten!AB3,0) -> Berechnung der Höhe und Tiefe einer Veranda | S11: =HLOOKUP(W2,Daten!$AC$1:$AE$23,Daten!AB23,0) -> Berechnung der Fensterelemente
B12: =HLOOKUP(W2,Daten!$AC$1:$AE$26,Daten!AB4,0) -> Höhe - Unterkante Rinne [mm] (H3) | C12: =HLOOKUP(W2,Daten!$AC$1:$AE$22,Daten!AB5,0) -> Bestelltiefe [mm] | D12: =HLOOKUP(W2,Daten!$AC$1:$AE$26,Daten!AB6,0) -> Höhe - Unterkante Wandprofil [mm] (H1) | E12: =HLOOKUP(W2,Daten!$AC$1:$AE$26,Daten!AB25,0) -> Dachüberstand [mm] (U1) | F12: =HLOOKUP(W2,Daten!$AC$1:$AE$26,Daten!AB7,0) -> Neigung [°] (α) | G12: =HLOOKUP(W2,Daten!$AC$1:$AE$27,Daten!AB27,0) -> Neigung [mm/m] | H12: =HLOOKUP(W2,Daten!$AC$1:$AE$26,Daten!AB26,0) -> Neigung Glas Ultraline [°] (β) | I12: =HLOOKUP(W2,Daten!$AC$1:$AE$22,Daten!AB8,0) -> Tiefe - Hinterkante Wandanschluss bis Mitte Pfosten [mm] (D1) | J12: =HLOOKUP(W2,Daten!$AC$1:$AE$22,Daten!AB9,0) -> Länge - Sparren Mitte [mm] (S1) | K12: =HLOOKUP(W2,Daten!$AC$1:$AE$22,Daten!AB10,0) -> Länge - Sparren Außen [mm] (S1) | L12: =HLOOKUP(W2,Daten!$AC$1:$AE$22,Daten!AB11,0) -> Tiefe - Hinterkante Wandanschluss bis Rinne Standard [mm] (D3) | M12: =HLOOKUP(W2,Daten!$AC$1:$AE$22,Daten!AB12,0) -> Tiefe - Hinterkante Wandanschluss bis Zierleiste rund [mm] (D3) | N12: =HLOOKUP(W2,Daten!$AC$1:$AE$22,Daten!AB13,0) -> Tiefe - Hinterkante Wandanschluss bis Zierleiste klassik [mm] (D3) | O12: =HLOOKUP(W2,Daten!$AC$1:$AE$22,Daten!AB14,0) -> Tiefe - Hinterkante Wandanschluss bis Innenkante Pfosten [mm] (D2) | P12: =HLOOKUP(W2,Daten!$AC$1:$AE$22,Daten!AB15,0) -> Höhe - Oberkante Wandprofil [mm] (H2) | Q12: =HLOOKUP(W2,Daten!$AC$1:$AE$22,Daten!AB21,0) -> Hinterkante Wandanschluss bis Außenkante Pfosten [mm] (D4) | R12: =HLOOKUP(W2,Daten!$AC$1:$AE$22,Daten!AB22,0) -> Hinterkante Wandanschluss bis Außenkante Pfosten [mm] (D5) | S12: =HLOOKUP(W2,Daten!$AC$1:$AE$22,Daten!AB16,0) -> Fensterhöhe Rinnenseite [mm] | T12: =HLOOKUP(W2,Daten!$AC$1:$AE$22,Daten!AB17,0) -> Fensterbreite [mm] | U12: =HLOOKUP(W2,Daten!$AC$1:$AE$22,Daten!AB18,0) -> Keilhöhe Rinnenseite [mm] | V12: =HLOOKUP(W2,Daten!$AC$1:$AE$22,Daten!AB19,0) -> Keilhöhe Hausseite [mm] | W12: =HLOOKUP(W2,Daten!$AC$1:$AE$22,Daten!AB20,0) -> Fensterhöhe Hausseite [mm]
A17: Type
A18: Skyline Freistand | B18: 2300 | C18: 5000 | D18: =Daten!D29 -> 2300 | E18: =Daten!E29 -> - | F18: =Daten!F29 -> - | G18: =Daten!G29 -> - | H18: =Daten!H29 -> 1.1326514 | I18: =Daten!I29 -> 4760 | J18: =Daten!J29 -> 4874 | K18: =Daten!K29 -> 4874 | ... W18: =Daten!W29 -> 2300
A21: Gelbe Zellen manuell ausfüllen!

Sheet Carport
U1: =Orangeline!U1 -> 45919 | W1: TFl
U2: =HLOOKUP(W2,Daten!$AC$1:$AE$24,Daten!AB24,0) -> Sprache | W2: GER
B10: =IFERROR(IF(B18="-","= 0 mm","= " & TEXT(B18,"#")&" mm"),"") -> = 2300 mm | C10: =IFERROR(IF(C18="-","= 0 mm","= " & TEXT(C18,"#")&" mm"),"") -> = 5000 mm | D10: =IFERROR(IF(D18="-","= 0 mm","= " & TEXT(D18,"#")&" mm"),"") -> = 2300 mm | E10: =IFERROR(IF(E18="-","0 mm =",TEXT(E18,"#")&" mm ="),"") -> 0 mm = | F10: =IFERROR(IF(F18="-","= 0°","= " & TEXT(F18,"0,0")&"°"),"") -> = 0° | G10: =IFERROR(IF(G18="-","= 0 mm/m","= " & TEXT(G18,"0,0")&" mm/m"),"") -> = 0 mm/m | H10: =IFERROR(IF(H18="-","= 0°","= " & TEXT(H18,"0,0")&"°"),"") -> = 0,3° | I10: =IFERROR(IF(I18="-","= 0 mm","= " & TEXT(I18,"#")&" mm"),"") -> = 4920 mm | J10: =IFERROR(IF(J18="-","= 0 mm","= " & TEXT(J18,"#")&" mm"),"") -> = 0 mm | K10: =IFERROR(IF(K18="-","= 0 mm","= " & TEXT(K18,"#")&" mm"),"") -> = 4916 mm | L10: =IFERROR(IF(L18="-","= 0 mm","= " & TEXT(L18,"#")&" mm"),"") -> = 5000 mm | M10: =IFERROR(IF(M18="-","= 0 mm","= " & TEXT(M18,"#")&" mm"),"") -> = 0 mm | N10: =IFERROR(IF(N18="-","= 0 mm","= " & TEXT(N18,"#")&" mm"),"") -> = 0 mm | O10: =IFERROR(IF(O18="-","= 0 mm","= " & TEXT(O18,"#")&" mm"),"") -> = 4840 mm | P10: =IFERROR(IF(P18="-","= 0 mm","= " & TEXT(P18,"#")&" mm"),"") -> = 2542 mm | ... W10: =IFERROR(IF(W18="-","= 0 mm","= " & TEXT(W18,"#")&" mm"),"") -> = 2300 mm
A11: =HLOOKUP(W2,Daten!$AC$1:$AE$22,Daten!AB3,0) -> Berechnung der Höhe und Tiefe einer Veranda | S11: =HLOOKUP(W2,Daten!$AC$1:$AE$23,Daten!AB23,0) -> Berechnung der Fensterelemente
B12: =HLOOKUP(W2,Daten!$AC$1:$AE$26,Daten!AB4,0) -> Höhe - Unterkante Rinne [mm] (H3) | C12: =HLOOKUP(W2,Daten!$AC$1:$AE$22,Daten!AB5,0) -> Bestelltiefe [mm] | D12: =HLOOKUP(W2,Daten!$AC$1:$AE$26,Daten!AB6,0) -> Höhe - Unterkante Wandprofil [mm] (H1) | E12: =HLOOKUP(W2,Daten!$AC$1:$AE$26,Daten!AB25,0) -> Dachüberstand [mm] (U1) | F12: =HLOOKUP(W2,Daten!$AC$1:$AE$26,Daten!AB7,0) -> Neigung [°] (α) | G12: =HLOOKUP(W2,Daten!$AC$1:$AE$27,Daten!AB27,0) -> Neigung [mm/m] | H12: =HLOOKUP(W2,Daten!$AC$1:$AE$26,Daten!AB26,0) -> Neigung Glas Ultraline [°] (β) | I12: =HLOOKUP(W2,Daten!$AC$1:$AE$22,Daten!AB8,0) -> Tiefe - Hinterkante Wandanschluss bis Mitte Pfosten [mm] (D1) | J12: =HLOOKUP(W2,Daten!$AC$1:$AE$22,Daten!AB9,0) -> Länge - Sparren Mitte [mm] (S1) | K12: =HLOOKUP(W2,Daten!$AC$1:$AE$22,Daten!AB10,0) -> Länge - Sparren Außen [mm] (S1) | L12: =HLOOKUP(W2,Daten!$AC$1:$AE$22,Daten!AB11,0) -> Tiefe - Hinterkante Wandanschluss bis Rinne Standard [mm] (D3) | M12: =HLOOKUP(W2,Daten!$AC$1:$AE$22,Daten!AB12,0) -> Tiefe - Hinterkante Wandanschluss bis Zierleiste rund [mm] (D3) | N12: =HLOOKUP(W2,Daten!$AC$1:$AE$22,Daten!AB13,0) -> Tiefe - Hinterkante Wandanschluss bis Zierleiste klassik [mm] (D3) | O12: =HLOOKUP(W2,Daten!$AC$1:$AE$22,Daten!AB14,0) -> Tiefe - Hinterkante Wandanschluss bis Innenkante Pfosten [mm] (D2) | P12: =HLOOKUP(W2,Daten!$AC$1:$AE$22,Daten!AB15,0) -> Höhe - Oberkante Wandprofil [mm] (H2) | Q12: =HLOOKUP(W2,Daten!$AC$1:$AE$22,Daten!AB21,0) -> Hinterkante Wandanschluss bis Außenkante Pfosten [mm] (D4) | R12: =HLOOKUP(W2,Daten!$AC$1:$AE$22,Daten!AB22,0) -> Hinterkante Wandanschluss bis Außenkante Pfosten [mm] (D5) | S12: =HLOOKUP(W2,Daten!$AC$1:$AE$22,Daten!AB16,0) -> Fensterhöhe Rinnenseite [mm] | T12: =HLOOKUP(W2,Daten!$AC$1:$AE$22,Daten!AB17,0) -> Fensterbreite [mm] | U12: =HLOOKUP(W2,Daten!$AC$1:$AE$22,Daten!AB18,0) -> Keilhöhe Rinnenseite [mm] | V12: =HLOOKUP(W2,Daten!$AC$1:$AE$22,Daten!AB19,0) -> Keilhöhe Hausseite [mm] | W12: =HLOOKUP(W2,Daten!$AC$1:$AE$22,Daten!AB20,0) -> Fensterhöhe Hausseite [mm]
A17: Type
A18: Carport | B18: 2300 | C18: 5000 | D18: =Daten!D30 -> 2300 | E18: =Daten!E30 -> - | F18: =Daten!F30 -> - | G18: =Daten!G30 -> - | H18: =Daten!H30 -> 0.33491932 | I18: =Daten!I30 -> 4920 | J18: =Daten!J30 -> - | K18: =Daten!K30 -> 4916 | ... W18: =Daten!W30 -> 2300
A21: Gelbe Zellen manuell ausfüllen!

Sheet Carport Freistand
U1: =Orangeline!U1 -> 45919 | W1: TFl
U2: =HLOOKUP(W2,Daten!$AC$1:$AE$24,Daten!AB24,0) -> Sprache | W2: GER
B10: =IFERROR(IF(B18="-","= 0 mm","= " & TEXT(B18,"#")&" mm"),"") -> = 2300 mm | C10: =IFERROR(IF(C18="-","= 0 mm","= " & TEXT(C18,"#")&" mm"),"") -> = 5000 mm | D10: =IFERROR(IF(D18="-","= 0 mm","= " & TEXT(D18,"#")&" mm"),"") -> = 2300 mm | E10: =IFERROR(IF(E18="-","0 mm =",TEXT(E18,"#")&" mm ="),"") -> 0 mm = | F10: =IFERROR(IF(F18="-","= 0°","= " & TEXT(F18,"0,0")&"°"),"") -> = 0° | G10: =IFERROR(IF(G18="-","= 0 mm/m","= " & TEXT(G18,"0,0")&" mm/m"),"") -> = 0 mm/m | H10: =IFERROR(IF(H18="-","= 0°","= " & TEXT(H18,"0,0")&"°"),"") -> = 0,3° | I10: =IFERROR(IF(I18="-","= 0 mm","= " & TEXT(I18,"#")&" mm"),"") -> = 4760 mm | J10: =IFERROR(IF(J18="-","= 0 mm","= " & TEXT(J18,"#")&" mm"),"") -> = 0 mm | K10: =IFERROR(IF(K18="-","= 0 mm","= " & TEXT(K18,"#")&" mm"),"") -> = 4874 mm | L10: =IFERROR(IF(L18="-","= 0 mm","= " & TEXT(L18,"#")&" mm"),"") -> = 4840 mm | M10: =IFERROR(IF(M18="-","= 0 mm","= " & TEXT(M18,"#")&" mm"),"") -> = 0 mm | N10: =IFERROR(IF(N18="-","= 0 mm","= " & TEXT(N18,"#")&" mm"),"") -> = 0 mm | O10: =IFERROR(IF(O18="-","= 0 mm","= " & TEXT(O18,"#")&" mm"),"") -> = 4680 mm | P10: =IFERROR(IF(P18="-","= 0 mm","= " & TEXT(P18,"#")&" mm"),"") -> = 2542 mm | ... W10: =IFERROR(IF(W18="-","= 0 mm","= " & TEXT(W18,"#")&" mm"),"") -> = 2300 mm
A11: =HLOOKUP(W2,Daten!$AC$1:$AE$22,Daten!AB3,0) -> Berechnung der Höhe und Tiefe einer Veranda | S11: =HLOOKUP(W2,Daten!$AC$1:$AE$23,Daten!AB23,0) -> Berechnung der Fensterelemente
